
Train Epoch: 1 [0/50000 (0%)]	Loss: 2.297424
Train Epoch: 1 [3000/50000 (6%)]	Loss: 2.268401
Train Epoch: 1 [6000/50000 (12%)]	Loss: 2.216071
Train Epoch: 1 [9000/50000 (18%)]	Loss: 2.226330
Train Epoch: 1 [12000/50000 (24%)]	Loss: 2.095092
Train Epoch: 1 [15000/50000 (30%)]	Loss: 2.063625
Train Epoch: 1 [18000/50000 (36%)]	Loss: 2.098092
Train Epoch: 1 [21000/50000 (42%)]	Loss: 1.957162
Train Epoch: 1 [24000/50000 (48%)]	Loss: 2.035123
Train Epoch: 1 [27000/50000 (54%)]	Loss: 1.873635
Train Epoch: 1 [30000/50000 (60%)]	Loss: 1.812725
Train Epoch: 1 [33000/50000 (66%)]	Loss: 1.861170
Train Epoch: 1 [36000/50000 (72%)]	Loss: 1.978486
Train Epoch: 1 [39000/50000 (78%)]	Loss: 1.898484
Train Epoch: 1 [42000/50000 (84%)]	Loss: 1.878822
Train Epoch: 1 [45000/50000 (90%)]	Loss: 1.861502
Train Epoch: 1 [48000/50000 (96%)]	Loss: 1.830697
Average train loss: 2.0148729156045353. Epoch: 1
Test set: Average loss: 1.7724, Accuracy: 0.3742 (37%)
Train Epoch: 2 [0/50000 (0%)]	Loss: 1.548729
Train Epoch: 2 [3000/50000 (6%)]	Loss: 1.801307
Train Epoch: 2 [6000/50000 (12%)]	Loss: 1.731085
Train Epoch: 2 [9000/50000 (18%)]	Loss: 1.726625
Train Epoch: 2 [12000/50000 (24%)]	Loss: 1.748924
Train Epoch: 2 [15000/50000 (30%)]	Loss: 1.747748
Train Epoch: 2 [18000/50000 (36%)]	Loss: 1.553508
Train Epoch: 2 [21000/50000 (42%)]	Loss: 1.620065
Train Epoch: 2 [24000/50000 (48%)]	Loss: 1.539425
Train Epoch: 2 [27000/50000 (54%)]	Loss: 1.565540
Train Epoch: 2 [30000/50000 (60%)]	Loss: 1.638633
Train Epoch: 2 [33000/50000 (66%)]	Loss: 1.481734
Train Epoch: 2 [36000/50000 (72%)]	Loss: 1.552598
Train Epoch: 2 [39000/50000 (78%)]	Loss: 1.606521
Train Epoch: 2 [42000/50000 (84%)]	Loss: 1.548014
Train Epoch: 2 [45000/50000 (90%)]	Loss: 1.629910
Train Epoch: 2 [48000/50000 (96%)]	Loss: 1.467801
Average train loss: 1.6181273390265072. Epoch: 2
Test set: Average loss: 1.5610, Accuracy: 0.4436 (44%)
Train Epoch: 3 [0/50000 (0%)]	Loss: 1.575637
Train Epoch: 3 [3000/50000 (6%)]	Loss: 1.545151
Unexpected exception formatting exception. Falling back to standard exception
Traceback (most recent call last):
  File "/opt/conda/envs/speml24_2/lib/python3.8/site-packages/IPython/core/interactiveshell.py", line 3508, in run_code
    exec(code_obj, self.user_global_ns, self.user_ns)
  File "<ipython-input-11-8baa351479fb>", line 19, in <module>
    start_training(num_workers=NUM_WORKERS)
  File "<ipython-input-11-8baa351479fb>", line 6, in start_training
    train_loss = train_model(args, model, device, optimizer, epoch, num_workers)
  File "<ipython-input-9-f131b331fb9e>", line 13, in train_model
    loss.backward()
  File "/opt/conda/envs/speml24_2/lib/python3.8/site-packages/syft/generic/frameworks/hook/hook.py", line 209, in overloaded_native_method
    response = method(*new_args, **new_kwargs)
  File "/opt/conda/envs/speml24_2/lib/python3.8/site-packages/syft/generic/frameworks/hook/pointers.py", line 84, in overloaded_pointer_method
    response = owner.send_command(location, attr, self, args, kwargs)
  File "/opt/conda/envs/speml24_2/lib/python3.8/site-packages/syft/workers/base.py", line 525, in send_command
    ret_val = self.send_msg(message, location=recipient)
  File "/opt/conda/envs/speml24_2/lib/python3.8/site-packages/syft/workers/base.py", line 316, in send_msg
    bin_response = self._send_msg(bin_message, location)
  File "/opt/conda/envs/speml24_2/lib/python3.8/site-packages/syft/workers/virtual.py", line 12, in _send_msg
    return location._recv_msg(message)
  File "/opt/conda/envs/speml24_2/lib/python3.8/site-packages/syft/workers/virtual.py", line 22, in _recv_msg
    return self.recv_msg(message)
  File "/opt/conda/envs/speml24_2/lib/python3.8/site-packages/syft/workers/base.py", line 356, in recv_msg
    response = handler.handle(msg)
  File "/opt/conda/envs/speml24_2/lib/python3.8/site-packages/syft/generic/abstract/message_handler.py", line 20, in handle
    return self.routing_table[type(msg)](msg)
  File "/opt/conda/envs/speml24_2/lib/python3.8/site-packages/syft/workers/message_handler.py", line 55, in execute_tensor_command
    return self.execute_computation_action(cmd.action)
  File "/opt/conda/envs/speml24_2/lib/python3.8/site-packages/syft/workers/message_handler.py", line 97, in execute_computation_action
    response = getattr(_self, op_name)(*args_, **kwargs_)
  File "/opt/conda/envs/speml24_2/lib/python3.8/site-packages/syft/generic/frameworks/hook/hook.py", line 169, in overloaded_native_method
    raise route_method_exception(e, self, args, kwargs)
  File "/opt/conda/envs/speml24_2/lib/python3.8/site-packages/syft/generic/frameworks/hook/hook.py", line 165, in overloaded_native_method
    response = method(*args, **kwargs)
  File "/opt/conda/envs/speml24_2/lib/python3.8/site-packages/torch/tensor.py", line 195, in backward
    torch.autograd.backward(self, gradient, retain_graph, create_graph)
  File "/opt/conda/envs/speml24_2/lib/python3.8/site-packages/torch/autograd/__init__.py", line 97, in backward
    Variable._execution_engine.run_backward(
KeyboardInterrupt
During handling of the above exception, another exception occurred:
Traceback (most recent call last):
  File "/opt/conda/envs/speml24_2/lib/python3.8/site-packages/IPython/core/interactiveshell.py", line 2105, in showtraceback
    stb = self.InteractiveTB.structured_traceback(
  File "/opt/conda/envs/speml24_2/lib/python3.8/site-packages/IPython/core/ultratb.py", line 1396, in structured_traceback
    return FormattedTB.structured_traceback(
  File "/opt/conda/envs/speml24_2/lib/python3.8/site-packages/IPython/core/ultratb.py", line 1287, in structured_traceback
    return VerboseTB.structured_traceback(
  File "/opt/conda/envs/speml24_2/lib/python3.8/site-packages/IPython/core/ultratb.py", line 1140, in structured_traceback
    formatted_exception = self.format_exception_as_a_whole(etype, evalue, etb, number_of_lines_of_context,
  File "/opt/conda/envs/speml24_2/lib/python3.8/site-packages/IPython/core/ultratb.py", line 1030, in format_exception_as_a_whole
    self.get_records(etb, number_of_lines_of_context, tb_offset) if etb else []
  File "/opt/conda/envs/speml24_2/lib/python3.8/site-packages/IPython/core/ultratb.py", line 1098, in get_records
    mod = inspect.getmodule(cf.tb_frame)
  File "/opt/conda/envs/speml24_2/lib/python3.8/inspect.py", line 745, in getmodule
    if ismodule(module) and hasattr(module, '__file__'):
  File "/opt/conda/envs/speml24_2/lib/python3.8/site-packages/wandb/util.py", line 219, in __getattribute__
    state.load()
  File "/opt/conda/envs/speml24_2/lib/python3.8/site-packages/wandb/util.py", line 212, in load
    self.module.__spec__.loader.exec_module(self.module)
  File "<frozen importlib._bootstrap_external>", line 843, in exec_module
  File "<frozen importlib._bootstrap>", line 219, in _call_with_frames_removed
  File "/opt/conda/envs/speml24_2/lib/python3.8/site-packages/notebook/notebookapp.py", line 41, in <module>
    from jinja2 import Environment, FileSystemLoader
  File "/opt/conda/envs/speml24_2/lib/python3.8/site-packages/jinja2/__init__.py", line 12, in <module>
    from .environment import Environment
  File "/opt/conda/envs/speml24_2/lib/python3.8/site-packages/jinja2/environment.py", line 25, in <module>
    from .defaults import BLOCK_END_STRING
  File "/opt/conda/envs/speml24_2/lib/python3.8/site-packages/jinja2/defaults.py", line 3, in <module>
    from .filters import FILTERS as DEFAULT_FILTERS  # noqa: F401
  File "/opt/conda/envs/speml24_2/lib/python3.8/site-packages/jinja2/filters.py", line 13, in <module>
    from markupsafe import soft_unicode
ImportError: cannot import name 'soft_unicode' from 'markupsafe' (/opt/conda/envs/speml24_2/lib/python3.8/site-packages/markupsafe/__init__.py)
wojo-michaluk
